Workbook

Sheet Leer primero
A1: Herramientas cuantitativas · MAGS 2026
A2: Libro de práctica editable. Sin macros. Fecha: 2 de octubre de 2026.
A4: 1. Celdas azules: datos de entrada. Celdas verdes: fórmulas. Pulsa F9 para recalcular si corresponde.
A5: 2. Los gráficos son objetos nativos de Excel: puedes editar tipo, ejes, leyenda y series.
A6: 3. No insertes datos fuera del rango del gráfico sin ampliar manualmente sus referencias.
A7: 4. Chi Muestra usa los 247 registros individuales: placebo 2/9/16; p≈0,04631.
A8: 5. Chi guardada reproduce Análisis (3): placebo 6/13/8; p≈0,68903. No coincide con la base.
A9: 6. Chi ABC coincide con Muestra y Análisis (4); p≈0,04275.
A10: 7. Pearson es r. R² es el coeficiente de determinación; R²=r² en regresión simple con intercepto.
A11: 8. Erlang usa el caso 5 min de atención / 10 min de espera / 80%, sin macros.
A12: 9. Erlang permite comparar 1 a 40 personas por bloque. Si no hay solución dentro de ese límite muestra límite.
A13: 10. No uses los aranceles de clase como valores vigentes. Conserva los códigos como texto.
... A18: 15. Los valores en caché fueron calculados para facilitar la primera visualización; Excel recalcula las fórmulas.

Sheet Reg Intro
A1: Reg Intro
A2: Edita X e Y en azul. Gráfico XY nativo con tendencia lineal. Fórmulas se recalculan al abrir.
A4: Registro | B4: X | C4: Y | D4: Y estimada | E4: Residuo | G4: Indicador | H4: Valor
A5: Punto 1 | B5: 2 | C5: 15 | D5: =$H$6*B5+$H$7 -> 13.52809 | E5: =C5-D5 -> 1.4719101 | G5: r | H5: =CORREL(B5:B8,C5:C8) -> -0.95089198
A6: Punto 2 | B6: 5 | C6: 10 | D6: =$H$6*B6+$H$7 -> 11.455056 | E6: =C6-D6 -> -1.4550562 | G6: Pendiente m | H6: =SLOPE(C5:C8,B5:B8) -> -0.69101124
A7: Punto 3 | B7: 15 | C7: 3 | D7: =$H$6*B7+$H$7 -> 4.5449438 | E7: =C7-D7 -> -1.5449438 | G7: Intercepto b | H7: =INTERCEPT(C5:C8,B5:B8) -> 14.910112
A8: Punto 4 | B8: 18 | C8: 4 | D8: =$H$6*B8+$H$7 -> 2.4719101 | E8: =C8-D8 -> 1.5280899 | G8: R² | H8: =RSQ(C5:C8,B5:B8) -> 0.90419555
G9: X para predecir | H9: 2
G10: Y predicha | H10: =H6*H9+H7 -> 13.52809

Sheet Reg Paises
A1: Reg Paises
A2: Edita X e Y en azul. Gráfico XY nativo con tendencia lineal. Fórmulas se recalculan al abrir.
A4: Registro | B4: Ingreso per cápita PPP | C4: Esperanza vida (años) | D4: Y estimada | E4: Residuo | G4: Indicador | H4: Valor
A5: Afghanistan | B5: 800 | C5: 44.21 | D5: =$H$6*B5+$H$7 -> 63.850246 | E5: =C5-D5 -> -19.640246 | G5: r | H5: =CORREL(B5:B230,C5:C230) -> 0.5372179
A6: Albania | B6: 6000 | C6: 77.78 | D6: =$H$6*B6+$H$7 -> 65.637203 | E6: =C6-D6 -> 12.142797 | G6: Pendiente m | H6: =SLOPE(C5:C230,B5:B230) -> 0.00034364571
A7: Algeria | B7: 7000 | C7: 73.77 | D7: =$H$6*B7+$H$7 -> 65.980849 | E7: =C7-D7 -> 7.789151 | G7: Intercepto b | H7: =INTERCEPT(C5:C230,B5:B230) -> 63.575329
A8: American Samoa | B8: 8000 | C8: 76.45 | D8: =$H$6*B8+$H$7 -> 66.324495 | E8: =C8-D8 -> 10.125505 | G8: R² | H8: =RSQ(C5:C230,B5:B230) -> 0.28860307
A9: Andorra | B9: 42500 | C9: 83.53 | D9: =$H$6*B9+$H$7 -> 78.180272 | E9: =C9-D9 -> 5.3497283 | G9: X para predecir | H9: 800
A10: Angola | B10: 8800 | C10: 37.92 | D10: =$H$6*B10+$H$7 -> 66.599411 | E10: =C10-D10 -> -28.679411 | G10: Y predicha | H10: =H6*H9+H7 -> 63.850246
A11: Anguilla | B11: 8800 | C11: 80.53 | D11: =$H$6*B11+$H$7 -> 66.599411 | E11: =C11-D11 -> 13.930589
A12: Antigua and Barbuda | B12: 19000 | C12: 72.69 | D12: =$H$6*B12+$H$7 -> 70.104597 | E12: =C12-D12 -> 2.5854025
A13: Argentina | B13: 14200 | C13: 76.52 | D13: =$H$6*B13+$H$7 -> 68.455098 | E13: =C13-D13 -> 8.0649019
A14: Armenia | B14: 6400 | C14: 72.4 | D14: =$H$6*B14+$H$7 -> 65.774662 | E14: =C14-D14 -> 6.6253385
A15: Aruba | B15: 21800 | C15: 75.06 | D15: =$H$6*B15+$H$7 -> 71.066805 | E15: =C15-D15 -> 3.9931945
A16: Australia | B16: 38100 | C16: 80.73 | D16: =$H$6*B16+$H$7 -> 76.668231 | E16: =C16-D16 -> 4.0617694
A17: Austria | B17: 39200 | C17: 79.36 | D17: =$H$6*B17+$H$7 -> 77.046241 | E17: =C17-D17 -> 2.3137592
A18: Azerbaijan | B18: 9000 | C18: 66.31 | D18: =$H$6*B18+$H$7 -> 66.66814 | E18: =C18-D18 -> -0.35814039
A19: Bahamas | B19: 28600 | C19: 65.72 | D19: =$H$6*B19+$H$7 -> 73.403596 | E19: =C19-D19 -> -7.6835963
A20: Bahrain | B20: 37200 | C20: 74.92 | D20: =$H$6*B20+$H$7 -> 76.358949 | E20: =C20-D20 -> -1.4389494
A21: Bangladesh | B21: 1500 | C21: 63.21 | D21: =$H$6*B21+$H$7 -> 64.090798 | E21: =C21-D21 -> -0.88079757
A22: Barbados | B22: 19300 | C22: 73.21 | D22: =$H$6*B22+$H$7 -> 70.207691 | E22: =C22-D22 -> 3.0023088
... A230: Zimbabwe | B230: 200 | C230: 39.73 | D230: =$H$6*B230+$H$7 -> 63.644058 | E230: =C230-D230 -> -23.914058

Sheet Reg Salud
A1: Reg Salud
A2: Edita X e Y en azul. Gráfico XY nativo con tendencia lineal. Fórmulas se recalculan al abrir.
A4: Registro | B4: Administrativos activos | C4: Espera (min) | D4: Y estimada | E4: Residuo | G4: Indicador | H4: Valor
A5: Jornada 1 | B5: 1 | C5: 72 | D5: =$H$6*B5+$H$7 -> 71.904762 | E5: =C5-D5 -> 0.095238095 | G5: r | H5: =CORREL(B5:B10,C5:C10) -> -0.99623292
A6: Jornada 2 | B6: 2 | C6: 65 | D6: =$H$6*B6+$H$7 -> 65.87619 | E6: =C6-D6 -> -0.87619048 | G6: Pendiente m | H6: =SLOPE(C5:C10,B5:B10) -> -6.0285714
A7: Jornada 3 | B7: 3 | C7: 61 | D7: =$H$6*B7+$H$7 -> 59.847619 | E7: =C7-D7 -> 1.152381 | G7: Intercepto b | H7: =INTERCEPT(C5:C10,B5:B10) -> 77.933333
A8: Jornada 4 | B8: 4 | C8: 53 | D8: =$H$6*B8+$H$7 -> 53.819048 | E8: =C8-D8 -> -0.81904762 | G8: R² | H8: =RSQ(C5:C10,B5:B10) -> 0.99248003
A9: Jornada 5 | B9: 5 | C9: 49 | D9: =$H$6*B9+$H$7 -> 47.790476 | E9: =C9-D9 -> 1.2095238 | G9: X para predecir | H9: 1
A10: Jornada 6 | B10: 6 | C10: 41 | D10: =$H$6*B10+$H$7 -> 41.761905 | E10: =C10-D10 -> -0.76190476 | G10: Y predicha | H10: =H6*H9+H7 -> 71.904762

Sheet Reg Gaseosas
A1: Reg Gaseosas
A2: Edita X e Y en azul. Gráfico XY nativo con tendencia lineal. Fórmulas se recalculan al abrir.
A4: Registro | B4: Temperatura (°C) | C4: Ventas por hora | D4: Y estimada | E4: Residuo | G4: Indicador | H4: Valor
A5: Temperatura 0 | B5: 0 | C5: 0 | D5: =$H$6*B5+$H$7 -> 0.55714286 | E5: =C5-D5 -> -0.55714286 | G5: r | H5: =CORREL(B5:B24,C5:C24) -> 0.96905623
A6: Temperatura 1 | B6: 1 | C6: 3 | D6: =$H$6*B6+$H$7 -> 2.524812 | E6: =C6-D6 -> 0.47518797 | G6: Pendiente m | H6: =SLOPE(C5:C24,B5:B24) -> 1.9676692
A7: Temperatura 2 | B7: 2 | C7: 5 | D7: =$H$6*B7+$H$7 -> 4.4924812 | E7: =C7-D7 -> 0.5075188 | G7: Intercepto b | H7: =INTERCEPT(C5:C24,B5:B24) -> 0.55714286
A8: Temperatura 3 | B8: 3 | C8: 6 | D8: =$H$6*B8+$H$7 -> 6.4601504 | E8: =C8-D8 -> -0.46015038 | G8: R² | H8: =RSQ(C5:C24,B5:B24) -> 0.93906998
A9: Temperatura 4 | B9: 4 | C9: 9 | D9: =$H$6*B9+$H$7 -> 8.4278195 | E9: =C9-D9 -> 0.57218045 | G9: X para predecir | H9: 0
A10: Temperatura 5 | B10: 5 | C10: 12 | D10: =$H$6*B10+$H$7 -> 10.395489 | E10: =C10-D10 -> 1.6045113 | G10: Y predicha | H10: =H6*H9+H7 -> 0.55714286
A11: Temperatura 6 | B11: 6 | C11: 11 | D11: =$H$6*B11+$H$7 -> 12.363158 | E11: =C11-D11 -> -1.3631579
A12: Temperatura 7 | B12: 7 | C12: 13 | D12: =$H$6*B12+$H$7 -> 14.330827 | E12: =C12-D12 -> -1.3308271
A13: Temperatura 8 | B13: 8 | C13: 17 | D13: =$H$6*B13+$H$7 -> 16.298496 | E13: =C13-D13 -> 0.70150376
A14: Temperatura 9 | B14: 9 | C14: 15 | D14: =$H$6*B14+$H$7 -> 18.266165 | E14: =C14-D14 -> -3.2661654
A15: Temperatura 10 | B15: 10 | C15: 23 | D15: =$H$6*B15+$H$7 -> 20.233835 | E15: =C15-D15 -> 2.7661654
A16: Temperatura 11 | B16: 11 | C16: 19 | D16: =$H$6*B16+$H$7 -> 22.201504 | E16: =C16-D16 -> -3.2015038
A17: Temperatura 12 | B17: 12 | C17: 20 | D17: =$H$6*B17+$H$7 -> 24.169173 | E17: =C17-D17 -> -4.1691729
A18: Temperatura 13 | B18: 13 | C18: 29 | D18: =$H$6*B18+$H$7 -> 26.136842 | E18: =C18-D18 -> 2.8631579
A19: Temperatura 14 | B19: 14 | C19: 32 | D19: =$H$6*B19+$H$7 -> 28.104511 | E19: =C19-D19 -> 3.8954887
A20: Temperatura 15 | B20: 15 | C20: 36 | D20: =$H$6*B20+$H$7 -> 30.07218 | E20: =C20-D20 -> 5.9278195
A21: Temperatura 16 | B21: 16 | C21: 29 | D21: =$H$6*B21+$H$7 -> 32.03985 | E21: =C21-D21 -> -3.0398496
A22: Temperatura 17 | B22: 17 | C22: 37 | D22: =$H$6*B22+$H$7 -> 34.007519 | E22: =C22-D22 -> 2.9924812
... A24: Temperatura 19 | B24: 19 | C24: 32 | D24: =$H$6*B24+$H$7 -> 37.942857 | E24: =C24-D24 -> -5.9428571

Sheet Reg Cigarrillos
A1: Reg Cigarrillos
A2: Edita X e Y en azul. Gráfico XY nativo con tendencia lineal. Fórmulas se recalculan al abrir.
A4: Registro | B4: Temperatura (°C) | C4: Ventas por hora | D4: Y estimada | E4: Residuo | G4: Indicador | H4: Valor
A5: Temperatura 0 | B5: 0 | C5: 11 | D5: =$H$6*B5+$H$7 -> 8.9 | E5: =C5-D5 -> 2.1 | G5: r | H5: =CORREL(B5:B24,C5:C24) -> -0.87600109
A6: Temperatura 1 | B6: 1 | C6: 9 | D6: =$H$6*B6+$H$7 -> 8.5421053 | E6: =C6-D6 -> 0.45789474 | G6: Pendiente m | H6: =SLOPE(C5:C24,B5:B24) -> -0.35789474
A7: Temperatura 2 | B7: 2 | C7: 8 | D7: =$H$6*B7+$H$7 -> 8.1842105 | E7: =C7-D7 -> -0.18421053 | G7: Intercepto b | H7: =INTERCEPT(C5:C24,B5:B24) -> 8.9
A8: Temperatura 3 | B8: 3 | C8: 9 | D8: =$H$6*B8+$H$7 -> 7.8263158 | E8: =C8-D8 -> 1.1736842 | G8: R² | H8: =RSQ(C5:C24,B5:B24) -> 0.7673779
A9: Temperatura 4 | B9: 4 | C9: 8 | D9: =$H$6*B9+$H$7 -> 7.4684211 | E9: =C9-D9 -> 0.53157895 | G9: X para predecir | H9: 0
A10: Temperatura 5 | B10: 5 | C10: 6 | D10: =$H$6*B10+$H$7 -> 7.1105263 | E10: =C10-D10 -> -1.1105263 | G10: Y predicha | H10: =H6*H9+H7 -> 8.9
A11: Temperatura 6 | B11: 6 | C11: 6 | D11: =$H$6*B11+$H$7 -> 6.7526316 | E11: =C11-D11 -> -0.75263158
A12: Temperatura 7 | B12: 7 | C12: 3 | D12: =$H$6*B12+$H$7 -> 6.3947368 | E12: =C12-D12 -> -3.3947368
A13: Temperatura 8 | B13: 8 | C13: 5 | D13: =$H$6*B13+$H$7 -> 6.0368421 | E13: =C13-D13 -> -1.0368421
A14: Temperatura 9 | B14: 9 | C14: 5 | D14: =$H$6*B14+$H$7 -> 5.6789474 | E14: =C14-D14 -> -0.67894737
A15: Temperatura 10 | B15: 10 | C15: 7 | D15: =$H$6*B15+$H$7 -> 5.3210526 | E15: =C15-D15 -> 1.6789474
A16: Temperatura 11 | B16: 11 | C16: 5 | D16: =$H$6*B16+$H$7 -> 4.9631579 | E16: =C16-D16 -> 0.036842105
A17: Temperatura 12 | B17: 12 | C17: 4 | D17: =$H$6*B17+$H$7 -> 4.6052632 | E17: =C17-D17 -> -0.60526316
A18: Temperatura 13 | B18: 13 | C18: 4 | D18: =$H$6*B18+$H$7 -> 4.2473684 | E18: =C18-D18 -> -0.24736842
A19: Temperatura 14 | B19: 14 | C19: 4 | D19: =$H$6*B19+$H$7 -> 3.8894737 | E19: =C19-D19 -> 0.11052632
A20: Temperatura 15 | B20: 15 | C20: 4 | D20: =$H$6*B20+$H$7 -> 3.5315789 | E20: =C20-D20 -> 0.46842105
A21: Temperatura 16 | B21: 16 | C21: 3 | D21: =$H$6*B21+$H$7 -> 3.1736842 | E21: =C21-D21 -> -0.17368421
A22: Temperatura 17 | B22: 17 | C22: 3 | D22: =$H$6*B22+$H$7 -> 2.8157895 | E22: =C22-D22 -> 0.18421053
... A24: Temperatura 19 | B24: 19 | C24: 3 | D24: =$H$6*B24+$H$7 -> 2.1 | E24: =C24-D24 -> 0.9

Sheet Finanzas
A1: Correlación financiera · 20 semanas
A2: Variaciones en decimales: 0,025 equivale a 2,5%. Datos del archivo de clase.
A4: Semana | B4: Acción A | C4: S&P 500 | D4: Dólar | E4: Risk index
A5: 1 | B5: 0.025 | C5: 0.0127 | D5: 697 | E5: -0.01143
A6: 2 | B6: 0.0257 | C6: 0.0153 | D6: 701.8 | E6: -0.015453
A7: 3 | B7: -0.0075 | C7: -0.0116 | D7: 699.6 | E7: 0.010556
A8: 4 | B8: 0.0352 | C8: 0.031 | D8: 700.3 | E8: -0.03038
A9: 5 | B9: -0.0127 | C9: -0.0087 | D9: 703.8 | E9: 0.008961
A10: 6 | B10: 0.0201 | C10: 0.0153 | D10: 692.6 | E10: -0.016371
A11: 7 | B11: 0.0263 | C11: 0.0093 | D11: 707.4 | E11: -0.009393
A12: 8 | B12: -0.0116 | C12: -0.0136 | D12: 691 | E12: 0.01428
A13: 9 | B13: 0.0041 | C13: -0.0032 | D13: 706.9 | E13: 0.003232
A14: 10 | B14: 0.0537 | C14: 0.0163 | D14: 698.2 | E14: -0.015159
A15: 11 | B15: -0.011 | C15: -0.0136 | D15: 701 | E15: 0.012512
A16: 12 | B16: 0.0041 | C16: 0.0069 | D16: 691.9 | E16: -0.006417
... A24: 20 | B24: -0.0008 | C24: -0.01 | D24: 705.8 | E24: 0.0097
A27: Relación | B27: r
A28: Acción - S&P | B28: =CORREL(B5:B24,C5:C24) -> 0.89021334
A29: Acción - dólar | B29: =CORREL(B5:B24,D5:D24) -> -0.1608799
A30: Dólar - Risk | B30: =CORREL(D5:D24,E5:E24) -> 0.26461766
A31: S&P - Risk | B31: =CORREL(C5:C24,E5:E24) -> -0.99845061

Sheet Chi Muestra
A1: Chi Muestra
A2: Conteos recalculados desde Muestra. Discrepa de la tabla guardada en Análisis (3).
A4: Grupo | B4: Empeoramiento | C4: Mejoría | D4: Sin cambio | E4: Total
A5: Placebo | B5: 2 | C5: 9 | D5: 16 | E5: =SUM(B5:D5) -> 27
A6: Tratamiento | B6: 51 | C6: 88 | D6: 81 | E6: =SUM(B6:D6) -> 220
A7: TOTAL | B7: =SUM(B5:B6) -> 53 | C7: =SUM(C5:C6) -> 97 | D7: =SUM(D5:D6) -> 97 | E7: =SUM(E5:E6) -> 247
A11: Esperados | B11: Empeoramiento | C11: Mejoría | D11: Sin cambio
A12: Placebo | B12: =$E5*B$7/$E$7 -> 5.7935223 | C12: =$E5*C$7/$E$7 -> 10.603239 | D12: =$E5*D$7/$E$7 -> 10.603239
A13: Tratamiento | B13: =$E6*B$7/$E$7 -> 47.206478 | C13: =$E6*C$7/$E$7 -> 86.396761 | D13: =$E6*D$7/$E$7 -> 86.396761
A17: Contribución χ² | B17: Empeoramiento | C17: Mejoría | D17: Sin cambio
A18: Placebo | B18: =(B5-B12)^2/B12 -> 2.4839485 | C18: =(C5-C12)^2/C12 -> 0.24241412 | D18: =(D5-D12)^2/D12 -> 2.7468051
A19: Tratamiento | B19: =(B6-B13)^2/B13 -> 0.30484823 | C19: =(C6-C13)^2/C13 -> 0.029750824 | D19: =(D6-D13)^2/D13 -> 0.3371079
A23: χ² | B23: =SUM(B18:D19) -> 6.1448747
A24: Grados de libertad | B24: 2
A25: Valor p | B25: =CHITEST(B5:D6,B12:D13) -> 0.046308147
A26: α | B26: 0.05
A27: Decisión | B27: =IF(B25<B26,"Rechazar H0","No rechazar H0") -> Rechazar H0
A28: V Cramér | B28: =SQRT(B23/(E7*MIN(1,2))) -> 0.15772773
A31: Proporciones por grupo | B31: Empeoramiento | C31: Mejoría | D31: Sin cambio
A32: Placebo | B32: =B5/$E5 -> 0.074074074 | C32: =C5/$E5 -> 0.33333333 | D32: =D5/$E5 -> 0.59259259
A33: Tratamiento | B33: =B6/$E6 -> 0.23181818 | C33: =C6/$E6 -> 0.4 | D33: =D6/$E6 -> 0.36818182

Sheet Chi guardada
A1: Chi guardada
A2: Reproduce la tabla de Análisis (3), no los conteos de Muestra. Su texto p=0,032 es incorrecto.
A4: Grupo | B4: Empeoramiento | C4: Mejoría | D4: Sin cambio | E4: Total
A5: Placebo | B5: 6 | C5: 13 | D5: 8 | E5: =SUM(B5:D5) -> 27
A6: Tratamiento | B6: 51 | C6: 88 | D6: 81 | E6: =SUM(B6:D6) -> 220
A7: TOTAL | B7: =SUM(B5:B6) -> 57 | C7: =SUM(C5:C6) -> 101 | D7: =SUM(D5:D6) -> 89 | E7: =SUM(E5:E6) -> 247
A11: Esperados | B11: Empeoramiento | C11: Mejoría | D11: Sin cambio
A12: Placebo | B12: =$E5*B$7/$E$7 -> 6.2307692 | C12: =$E5*C$7/$E$7 -> 11.040486 | D12: =$E5*D$7/$E$7 -> 9.7287449
A13: Tratamiento | B13: =$E6*B$7/$E$7 -> 50.769231 | C13: =$E6*C$7/$E$7 -> 89.959514 | D13: =$E6*D$7/$E$7 -> 79.271255
A17: Contribución χ² | B17: Empeoramiento | C17: Mejoría | D17: Sin cambio
A18: Placebo | B18: =(B5-B12)^2/B12 -> 0.0085470085 | C18: =(C5-C12)^2/C12 -> 0.34778323 | D18: =(D5-D12)^2/D12 -> 0.30718855
A19: Tratamiento | B19: =(B6-B13)^2/B13 -> 0.001048951 | C19: =(C6-C13)^2/C13 -> 0.042682487 | D19: =(D6-D13)^2/D13 -> 0.037700413
A23: χ² | B23: =SUM(B18:D19) -> 0.74495064
A24: Grados de libertad | B24: 2
A25: Valor p | B25: =CHITEST(B5:D6,B12:D13) -> 0.68902666
A26: α | B26: 0.05
A27: Decisión | B27: =IF(B25<B26,"Rechazar H0","No rechazar H0") -> No rechazar H0
A28: V Cramér | B28: =SQRT(B23/(E7*MIN(1,2))) -> 0.054918071
A31: Proporciones por grupo | B31: Empeoramiento | C31: Mejoría | D31: Sin cambio
A32: Placebo | B32: =B5/$E5 -> 0.22222222 | C32: =C5/$E5 -> 0.48148148 | D32: =D5/$E5 -> 0.2962963
A33: Tratamiento | B33: =B6/$E6 -> 0.23181818 | C33: =C6/$E6 -> 0.4 | D33: =D6/$E6 -> 0.36818182

Sheet Chi ABC
A1: Chi ABC
A2: Tratamientos sin placebo. Coincide con la base Muestra. χ² global no identifica parejas diferentes.
A4: Grupo | B4: Empeoramiento | C4: Mejoría | D4: Sin cambio | E4: Total
A5: A | B5: 9 | C5: 36 | D5: 29 | E5: =SUM(B5:D5) -> 74
A6: B | B6: 21 | C6: 23 | D6: 30 | E6: =SUM(B6:D6) -> 74
A7: C | B7: 21 | C7: 29 | D7: 22 | E7: =SUM(B7:D7) -> 72
A8: TOTAL | B8: =SUM(B5:B7) -> 51 | C8: =SUM(C5:C7) -> 88 | D8: =SUM(D5:D7) -> 81 | E8: =SUM(E5:E7) -> 220
A11: Esperados | B11: Empeoramiento | C11: Mejoría | D11: Sin cambio
A12: A | B12: =$E5*B$8/$E$8 -> 17.154545 | C12: =$E5*C$8/$E$8 -> 29.6 | D12: =$E5*D$8/$E$8 -> 27.245455
A13: B | B13: =$E6*B$8/$E$8 -> 17.154545 | C13: =$E6*C$8/$E$8 -> 29.6 | D13: =$E6*D$8/$E$8 -> 27.245455
A14: C | B14: =$E7*B$8/$E$8 -> 16.690909 | C14: =$E7*C$8/$E$8 -> 28.8 | D14: =$E7*D$8/$E$8 -> 26.509091
A17: Contribución χ² | B17: Empeoramiento | C17: Mejoría | D17: Sin cambio
A18: A | B18: =(B5-B12)^2/B12 -> 3.8763261 | C18: =(C5-C12)^2/C12 -> 1.3837838 | D18: =(D5-D12)^2/D12 -> 0.11298875
A19: B | B19: =(B6-B13)^2/B13 -> 0.86201763 | C19: =(C6-C13)^2/C13 -> 1.4716216 | D19: =(D6-D13)^2/D13 -> 0.27848758
A20: C | B20: =(B7-B14)^2/B14 -> 1.1124777 | C20: =(C7-C14)^2/C14 -> 0.0013888889 | D20: =(D7-D14)^2/D14 -> 0.76697843
A23: χ² | B23: =SUM(B18:D20) -> 9.8660705
A24: Grados de libertad | B24: 4
A25: Valor p | B25: =CHITEST(B5:D7,B12:D14) -> 0.04274516
A26: α | B26: 0.05
A27: Decisión | B27: =IF(B25<B26,"Rechazar H0","No rechazar H0") -> Rechazar H0
A28: V Cramér | B28: =SQRT(B23/(E8*MIN(2,2))) -> 0.14974274
A31: Proporciones por grupo | B31: Empeoramiento | C31: Mejoría | D31: Sin cambio
A32: A | B32: =B5/$E5 -> 0.12162162 | C32: =C5/$E5 -> 0.48648649 | D32: =D5/$E5 -> 0.39189189
A33: B | B33: =B6/$E6 -> 0.28378378 | C33: =C6/$E6 -> 0.31081081 | D33: =D6/$E6 -> 0.40540541
A34: C | B34: =B7/$E7 -> 0.29166667 | C34: =C7/$E7 -> 0.40277778 | D34: =D7/$E7 -> 0.30555556

Sheet Base pacientes
A1: Datos individuales · Muestra
A2: 247 registros del archivo Chi cuadrado. Fuente para construir y actualizar una tabla dinámica.
A4: ID | B4: Tratamiento - Placebo | C4: Tratamiento | D4: Resultado
A5: 1 | B5: T | C5: A | D5: Mejoría
A6: 2 | B6: T | C6: A | D6: Sin cambio
A7: 3 | B7: T | C7: B | D7: Mejoría
A8: 4 | B8: T | C8: C | D8: Empeoramiento
A9: 5 | B9: T | C9: B | D9: Sin cambio
A10: 6 | B10: T | C10: A | D10: Mejoría
A11: 7 | B11: T | C11: C | D11: Sin cambio
A12: 8 | B12: T | C12: B | D12: Mejoría
A13: 9 | B13: T | C13: A | D13: Empeoramiento
A14: 10 | B14: T | C14: C | D14: Mejoría
A15: 11 | B15: T | C15: B | D15: Sin cambio
A16: 12 | B16: T | C16: A | D16: Mejoría
... A251: 247 | B251: P | C251: P | D251: Sin cambio

Sheet Arancel practica
A1: Búsqueda exacta · Arancel FNS de clase
A2: Valores del archivo; no se presentan como aranceles actuales. Códigos almacenados como texto.
A4: Código | B4: Prestación | C4: Total nivel 1 | D4: Total nivel 2 | E4: Total nivel 3
A5: 0101001 | B5: Consulta Medicina General | C5: 11000 | D5: 11780 | E5: 13780
A6: 0101201 | B6: Consulta Médica de Especialidad en Dermatología | C6: 15550 | D6: 20220 | E6: 24880
A7: 0101202 | B7: Consulta Médica de Especialidad en Geriatría | C7: 15550 | D7: 20220 | E7: 24880
A8: 0101203 | B8: Consulta Médica de Especialidad en Neurocirugía | C8: 15550 | D8: 20220 | E8: 24880
A9: 0101204 | B9: Consulta Médica de Especialidad en Oftalmología | C9: 15550 | D9: 20220 | E9: 24880
A10: 0101205 | B10: Consulta Médica de Especialidad en Otorrinolaringología | C10: 15550 | D10: 20220 | E10: 24880
A11: 0101206 | B11: Consulta Médica de Especialidad en Reumatología | C11: 15550 | D11: 20220 | E11: 24880
A12: 0101207 | B12: Consulta Médica de Especialidad en Endocrinología Adulto | C12: 15550 | D12: 20220 | E12: 24880
A13: 0101208 | B13: Consulta Médica de Especialidad en Endocrinología Pediátrica | C13: 15550 | D13: 20220 | E13: 24880
A14: 0101209 | B14: Consulta Médica de Especialidad en Neurología Adultos | C14: 15550 | D14: 20220 | E14: 24880
A15: 0101210 | B15: Consulta Médica de Especialidad en Neurología Pediátrica | C15: 15550 | D15: 20220 | E15: 24880
A16: 0101211 | B16: Consulta Médica de Especialidad en Oncología Médica | C16: 15550 | D16: 20220 | E16: 24880
A19: Código para buscar | B19: 0101001
A20: Nombre encontrado | B20: =IFERROR(VLOOKUP(B19,A5:E16,2,FALSE),"No encontrado") -> Consulta Medicina General
A23: Nivel | B23: Valor encontrado
A24: Nivel 1 | B24: =IFERROR(VLOOKUP($B$19,$A$5:$E$16,3,FALSE),0) -> 11000
A25: Nivel 2 | B25: =IFERROR(VLOOKUP($B$19,$A$5:$E$16,4,FALSE),0) -> 11780
A26: Nivel 3 | B26: =IFERROR(VLOOKUP($B$19,$A$5:$E$16,5,FALSE),0) -> 13780

Sheet Base continentes
A1: Países y territorios de la clase
A2: 226 registros históricos. Fuente para crear una tabla dinámica.
A4: País | B4: Esperanza vida | C4: Continente | D4: Ingreso PPP
A5: Afghanistan | B5: 44.21 | C5: Asia | D5: 800
A6: Albania | B6: 77.78 | C6: Europa | D6: 6000
A7: Algeria | B7: 73.77 | C7: Africa | D7: 7000
A8: Samoa | B8: 76.45 | C8: Oceanía | D8: 8000
A9: Andorra | B9: 83.53 | C9: Europa | D9: 42500
A10: Angola | B10: 37.92 | C10: Africa | D10: 8800
A11: Anguilla | B11: 80.53 | C11: Norte América | D11: 8800
A12: Antigua and Barbuda | B12: 72.69 | C12: Norte América | D12: 19000
A13: Argentina | B13: 76.52 | C13: Sur América | D13: 14200
A14: Armenia | B14: 72.4 | C14: Asia | D14: 6400
A15: Aruba | B15: 75.06 | C15: Norte América | D15: 21800
A16: Australia | B16: 80.73 | C16: Oceanía | D16: 38100
... A230: Zimbabwe | B230: 39.73 | C230: Africa | D230: 200

Sheet Continentes
A1: Resumen de países por continente
A2: Resumen por fórmulas, equivalente al ejercicio de tabla dinámica. Promedios simples por país.
A4: Continente | B4: Recuento | C4: Vida promedio | D4: PPP promedio | E4: PPP máximo
A5: Asia | B5: =COUNTIF('Base continentes'!$C$5:$C$230,A5) -> 51 | C5: =AVERAGEIF('Base continentes'!$C$5:$C$230,A5,'Base continentes'!$B$5:$B$230) -> 70.967647 | D5: =AVERAGEIF('Base continentes'!$C$5:$C$230,A5,'Base continentes'!$D$5:$D$230) -> 15341.176 | E5: 103500
A6: Europa | B6: =COUNTIF('Base continentes'!$C$5:$C$230,A6) -> 49 | C6: =AVERAGEIF('Base continentes'!$C$5:$C$230,A6,'Base continentes'!$B$5:$B$230) -> 76.928776 | D6: =AVERAGEIF('Base continentes'!$C$5:$C$230,A6,'Base continentes'!$D$5:$D$230) -> 30069.388 | E6: 118000
A7: Africa | B7: =COUNTIF('Base continentes'!$C$5:$C$230,A7) -> 56 | C7: =AVERAGEIF('Base continentes'!$C$5:$C$230,A7,'Base continentes'!$B$5:$B$230) -> 54.164286 | D7: =AVERAGEIF('Base continentes'!$C$5:$C$230,A7,'Base continentes'!$D$5:$D$230) -> 3916.0714 | E7: 31400
A8: Oceanía | B8: =COUNTIF('Base continentes'!$C$5:$C$230,A8) -> 23 | C8: =AVERAGEIF('Base continentes'!$C$5:$C$230,A8,'Base continentes'!$B$5:$B$230) -> 71.348696 | D8: =AVERAGEIF('Base continentes'!$C$5:$C$230,A8,'Base continentes'!$D$5:$D$230) -> 8782.6087 | E8: 38100
A9: Norte América | B9: =COUNTIF('Base continentes'!$C$5:$C$230,A9) -> 35 | C9: =AVERAGEIF('Base continentes'!$C$5:$C$230,A9,'Base continentes'!$B$5:$B$230) -> 74.025714 | D9: =AVERAGEIF('Base continentes'!$C$5:$C$230,A9,'Base continentes'!$D$5:$D$230) -> 17160 | E9: 69900
A10: Sur América | B10: =COUNTIF('Base continentes'!$C$5:$C$230,A10) -> 12 | C10: =AVERAGEIF('Base continentes'!$C$5:$C$230,A10,'Base continentes'!$B$5:$B$230) -> 73.13 | D10: =AVERAGEIF('Base continentes'!$C$5:$C$230,A10,'Base continentes'!$D$5:$D$230) -> 9266.6667 | E10: 14900
A12: PPP máximo: valores de referencia; calcula Máximo en tabla dinámica para practicar.

Sheet Salud resumen
A1: Egresos simulados · Tablas dinámicas
A2: Fuente de seis egresos para practicar recuento, suma y promedio.
A4: ID | B4: Servicio | C4: Estadía (días) | D4: Costo ($)
A5: 1 | B5: Medicina | C5: 3 | D5: 120000
A6: 2 | B6: Medicina | C6: 5 | D6: 200000
A7: 3 | B7: Medicina | C7: 4 | D7: 160000
A8: 4 | B8: Cirugía | C8: 2 | D8: 300000
A9: 5 | B9: Cirugía | C9: 6 | D9: 500000
A10: 6 | B10: Cirugía | C10: 4 | D10: 400000
A13: Servicio | B13: Egresos | C13: Estadía promedio | D13: Costo total
A14: Medicina | B14: =COUNTIF($B$5:$B$10,A14) -> 3 | C14: =AVERAGEIF($B$5:$B$10,A14,$C$5:$C$10) -> 4 | D14: =SUMIF($B$5:$B$10,A14,$D$5:$D$10) -> 480000
A15: Cirugía | B15: =COUNTIF($B$5:$B$10,A15) -> 3 | C15: =AVERAGEIF($B$5:$B$10,A15,$C$5:$C$10) -> 4 | D15: =SUMIF($B$5:$B$10,A15,$D$5:$D$10) -> 1200000

Sheet Erlang horas
A1: Erlang C · Consultorio Salud Viva
A2: Compara 1–40 personas activas por hora. Sin solución muestra límite. Los candidatos están a la derecha.
A4: Atención h (min) | B4: 5 | C4: Espera t (min) | D4: 10 | E4: Meta SL | F4: 0.8 | G4: Ocupación máx. | H4: 1 | I4: No disponibilidad | J4: 0
A6: Desde | B6: Llegadas/h | C6: Carga A | D6: Activos mínimos | E6: Ocupación | F6: P espera | G6: SL | H6: Wq (min) | I6: Programados | L6: c | M6: Erlang B | N6: ρ | O6: P espera | P6: SL | Q6: c factible
A7: 08:00 | B7: 18 | C7: =B7*$B$4/60 -> 1.5 | D7: =IF(COUNT(Q7:Q46)=0,"Límite 40",MIN(Q7:Q46)) -> 3 | E7: =C7/D7 -> 0.5 | F7: =INDEX(O7:O46,D7) -> 0.23684211 | G7: =INDEX(P7:P46,D7) -> 0.98820833 | H7: =F7*$B$4/(D7-C7) -> 0.78947368 | I7: =ROUNDUP(D7/(1-$J$4),0) -> 3 | L7: 1 | M7: =$C$7/(1+$C$7) -> 0.6 | N7: =$C$7/L7 -> 1.5 | O7: =IF(L7>$C$7,M7/(1-N7+N7*M7),1) -> 1 | P7: =IF(L7>$C$7,1-O7*EXP(-(L7-$C$7)*$D$4/$B$4),0) -> 0 | Q7: =IF(AND(L7>$C$7,P7>=$F$4,N7<=$H$4),L7,"")
A8: 09:00 | B8: 30 | C8: =B8*$B$4/60 -> 2.5 | D8: =IF(COUNT(Q49:Q88)=0,"Límite 40",MIN(Q49:Q88)) -> 4 | E8: =C8/D8 -> 0.625 | F8: =INDEX(O49:O88,D8) -> 0.3198567 | G8: =INDEX(P49:P88,D8) -> 0.98407527 | H8: =F8*$B$4/(D8-C8) -> 1.066189 | I8: =ROUNDUP(D8/(1-$J$4),0) -> 4 | L8: 2 | M8: =$C$7*M7/(L8+$C$7*M7) -> 0.31034483 | N8: =$C$7/L8 -> 0.75 | O8: =IF(L8>$C$7,M8/(1-N8+N8*M8),1) -> 0.64285714 | P8: =IF(L8>$C$7,1-O8*EXP(-(L8-$C$7)*$D$4/$B$4),0) -> 0.76350607 | Q8: =IF(AND(L8>$C$7,P8>=$F$4,N8<=$H$4),L8,"")
A9: 10:00 | B9: 42 | C9: =B9*$B$4/60 -> 3.5 | D9: =IF(COUNT(Q91:Q130)=0,"Límite 40",MIN(Q91:Q130)) -> 5 | E9: =C9/D9 -> 0.7 | F9: =INDEX(O91:O130,D9) -> 0.37783823 | G9: =INDEX(P91:P130,D9) -> 0.98118854 | H9: =F9*$B$4/(D9-C9) -> 1.2594608 | I9: =ROUNDUP(D9/(1-$J$4),0) -> 5 | L9: 3 | M9: =$C$7*M8/(L9+$C$7*M8) -> 0.13432836 | N9: =$C$7/L9 -> 0.5 | O9: =IF(L9>$C$7,M9/(1-N9+N9*M9),1) -> 0.23684211 | P9: =IF(L9>$C$7,1-O9*EXP(-(L9-$C$7)*$D$4/$B$4),0) -> 0.98820833 | Q9: =IF(AND(L9>$C$7,P9>=$F$4,N9<=$H$4),L9,"") -> 3
A10: 11:00 | B10: 36 | C10: =B10*$B$4/60 -> 3 | D10: =IF(COUNT(Q133:Q172)=0,"Límite 40",MIN(Q133:Q172)) -> 4 | E10: =C10/D10 -> 0.75 | F10: =INDEX(O133:O172,D10) -> 0.50943396 | G10: =INDEX(P133:P172,D10) -> 0.93105561 | H10: =F10*$B$4/(D10-C10) -> 2.5471698 | I10: =ROUNDUP(D10/(1-$J$4),0) -> 4 | L10: 4 | M10: =$C$7*M9/(L10+$C$7*M9) -> 0.047957371 | N10: =$C$7/L10 -> 0.375 | O10: =IF(L10>$C$7,M10/(1-N10+N10*M10),1) -> 0.074585635 | P10: =IF(L10>$C$7,1-O10*EXP(-(L10-$C$7)*$D$4/$B$4),0) -> 0.99949745 | Q10: =IF(AND(L10>$C$7,P10>=$F$4,N10<=$H$4),L10,"") -> 4
A11: 12:00 | B11: 24 | C11: =B11*$B$4/60 -> 2 | D11: =IF(COUNT(Q175:Q214)=0,"Límite 40",MIN(Q175:Q214)) -> 3 | E11: =C11/D11 -> 0.66666667 | F11: =INDEX(O175:O214,D11) -> 0.44444444 | G11: =INDEX(P175:P214,D11) -> 0.93985099 | H11: =F11*$B$4/(D11-C11) -> 2.2222222 | I11: =ROUNDUP(D11/(1-$J$4),0) -> 3 | L11: 5 | M11: =$C$7*M10/(L11+$C$7*M10) -> 0.014183155 | N11: =$C$7/L11 -> 0.3 | O11: =IF(L11>$C$7,M11/(1-N11+N11*M11),1) -> 0.020139234 | P11: =IF(L11>$C$7,1-O11*EXP(-(L11-$C$7)*$D$4/$B$4),0) -> 0.99998164 | Q11: =IF(AND(L11>$C$7,P11>=$F$4,N11<=$H$4),L11,"") -> 5
A12: 13:00 | B12: 15 | C12: =B12*$B$4/60 -> 1.25 | D12: =IF(COUNT(Q217:Q256)=0,"Límite 40",MIN(Q217:Q256)) -> 2 | E12: =C12/D12 -> 0.625 | F12: =INDEX(O217:O256,D12) -> 0.48076923 | G12: =INDEX(P217:P256,D12) -> 0.89272588 | H12: =F12*$B$4/(D12-C12) -> 3.2051282 | I12: =ROUNDUP(D12/(1-$J$4),0) -> 2 | L12: 6 | M12: =$C$7*M11/(L12+$C$7*M11) -> 0.0035332606 | N12: =$C$7/L12 -> 0.25 | O12: =IF(L12>$C$7,M12/(1-N12+N12*M12),1) -> 0.0047054723 | P12: =IF(L12>$C$7,1-O12*EXP(-(L12-$C$7)*$D$4/$B$4),0) -> 0.99999942 | Q12: =IF(AND(L12>$C$7,P12>=$F$4,N12<=$H$4),L12,"") -> 6
A13: 14:00 | B13: 20 | C13: =B13*$B$4/60 -> 1.6666667 | D13: =IF(COUNT(Q259:Q298)=0,"Límite 40",MIN(Q259:Q298)) -> 3 | E13: =C13/D13 -> 0.55555556 | F13: =INDEX(O259:O298,D13) -> 0.29976019 | G13: =INDEX(P259:P298,D13) -> 0.97917163 | H13: =F13*$B$4/(D13-C13) -> 1.1241007 | I13: =ROUNDUP(D13/(1-$J$4),0) -> 3 | L13: 7 | M13: =$C$7*M12/(L13+$C$7*M12) -> 0.00075655447 | N13: =$C$7/L13 -> 0.21428571 | O13: =IF(L13>$C$7,M13/(1-N13+N13*M13),1) -> 0.00096268887 | P13: =IF(L13>$C$7,1-O13*EXP(-(L13-$C$7)*$D$4/$B$4),0) -> 0.99999998 | Q13: =IF(AND(L13>$C$7,P13>=$F$4,N13<=$H$4),L13,"") -> 7
A14: 15:00 | B14: 28 | C14: =B14*$B$4/60 -> 2.3333333 | D14: =IF(COUNT(Q301:Q340)=0,"Límite 40",MIN(Q301:Q340)) -> 3 | E14: =C14/D14 -> 0.77777778 | F14: =INDEX(O301:O340,D14) -> 0.6114082 | G14: =INDEX(P301:P340,D14) -> 0.83883455 | H14: =F14*$B$4/(D14-C14) -> 4.5855615 | I14: =ROUNDUP(D14/(1-$J$4),0) -> 3 | L14: 8 | M14: =$C$7*M13/(L14+$C$7*M13) -> 0.00014183384 | N14: =$C$7/L14 -> 0.1875 | O14: =IF(L14>$C$7,M14/(1-N14+N14*M14),1) -> 0.00017455902 | P14: =IF(L14>$C$7,1-O14*EXP(-(L14-$C$7)*$D$4/$B$4),0) -> 1 | Q14: =IF(AND(L14>$C$7,P14>=$F$4,N14<=$H$4),L14,"") -> 8
A15: 16:00 | B15: 22 | C15: =B15*$B$4/60 -> 1.8333333 | D15: =IF(COUNT(Q343:Q382)=0,"Límite 40",MIN(Q343:Q382)) -> 3 | E15: =C15/D15 -> 0.61111111 | F15: =INDEX(O343:O382,D15) -> 0.36910704 | G15: =INDEX(P343:P382,D15) -> 0.96420696 | H15: =F15*$B$4/(D15-C15) -> 1.5818873 | I15: =ROUNDUP(D15/(1-$J$4),0) -> 3 | L15: 9 | M15: =$C$7*M14/(L15+$C$7*M14) -> 2.3638415e-05 | N15: =$C$7/L15 -> 0.16666667 | O15: =IF(L15>$C$7,M15/(1-N15+N15*M15),1) -> 2.8365964e-05 | P15: =IF(L15>$C$7,1-O15*EXP(-(L15-$C$7)*$D$4/$B$4),0) -> 1 | Q15: =IF(AND(L15>$C$7,P15>=$F$4,N15<=$H$4),L15,"") -> 9
L16: 10 | M16: =$C$7*M15/(L16+$C$7*M15) -> 3.5457497e-06 | N16: =$C$7/L16 -> 0.15 | O16: =IF(L16>$C$7,M16/(1-N16+N16*M16),1) -> 4.1714676e-06 | P16: =IF(L16>$C$7,1-O16*EXP(-(L16-$C$7)*$D$4/$B$4),0) -> 1 | Q16: =IF(AND(L16>$C$7,P16>=$F$4,N16<=$H$4),L16,"") -> 10
L17: 11 | M17: =$C$7*M16/(L17+$C$7*M16) -> 4.8351109e-07 | N17: =$C$7/L17 -> 0.13636364 | O17: =IF(L17>$C$7,M17/(1-N17+N17*M17),1) -> 5.598549e-07 | P17: =IF(L17>$C$7,1-O17*EXP(-(L17-$C$7)*$D$4/$B$4),0) -> 1 | Q17: =IF(AND(L17>$C$7,P17>=$F$4,N17<=$H$4),L17,"") -> 11
L18: 12 | M18: =$C$7*M17/(L18+$C$7*M17) -> 6.0438882e-08 | N18: =$C$7/L18 -> 0.125 | O18: =IF(L18>$C$7,M18/(1-N18+N18*M18),1) -> 6.9073008e-08 | P18: =IF(L18>$C$7,1-O18*EXP(-(L18-$C$7)*$D$4/$B$4),0) -> 1 | Q18: =IF(AND(L18>$C$7,P18>=$F$4,N18<=$H$4),L18,"") -> 12
L19: 13 | M19: =$C$7*M18/(L19+$C$7*M18) -> 6.9737172e-09 | N19: =$C$7/L19 -> 0.11538462 | O19: =IF(L19>$C$7,M19/(1-N19+N19*M19),1) -> 7.8833324e-09 | P19: =IF(L19>$C$7,1-O19*EXP(-(L19-$C$7)*$D$4/$B$4),0) -> 1 | Q19: =IF(AND(L19>$C$7,P19>=$F$4,N19<=$H$4),L19,"") -> 13
L20: 14 | M20: =$C$7*M19/(L20+$C$7*M19) -> 7.4718398e-10 | N20: =$C$7/L20 -> 0.10714286 | O20: =IF(L20>$C$7,M20/(1-N20+N20*M20),1) -> 8.3684606e-10 | P20: =IF(L20>$C$7,1-O20*EXP(-(L20-$C$7)*$D$4/$B$4),0) -> 1 | Q20: =IF(AND(L20>$C$7,P20>=$F$4,N20<=$H$4),L20,"") -> 14
L21: 15 | M21: =$C$7*M20/(L21+$C$7*M20) -> 7.4718398e-11 | N21: =$C$7/L21 -> 0.1 | O21: =IF(L21>$C$7,M21/(1-N21+N21*M21),1) -> 8.3020442e-11 | P21: =IF(L21>$C$7,1-O21*EXP(-(L21-$C$7)*$D$4/$B$4),0) -> 1 | Q21: =IF(AND(L21>$C$7,P21>=$F$4,N21<=$H$4),L21,"") -> 15
L22: 16 | M22: =$C$7*M21/(L22+$C$7*M21) -> 7.0048498e-12 | N22: =$C$7/L22 -> 0.09375 | O22: =IF(L22>$C$7,M22/(1-N22+N22*M22),1) -> 7.7294894e-12 | P22: =IF(L22>$C$7,1-O22*EXP(-(L22-$C$7)*$D$4/$B$4),0) -> 1 | Q22: =IF(AND(L22>$C$7,P22>=$F$4,N22<=$H$4),L22,"") -> 16
L23: 17 | M23: =$C$7*M22/(L23+$C$7*M22) -> 6.1807498e-13 | N23: =$C$7/L23 -> 0.088235294 | O23: =IF(L23>$C$7,M23/(1-N23+N23*M23),1) -> 6.7788869e-13 | P23: =IF(L23>$C$7,1-O23*EXP(-(L23-$C$7)*$D$4/$B$4),0) -> 1 | Q23: =IF(AND(L23>$C$7,P23>=$F$4,N23<=$H$4),L23,"") -> 17
L24: 18 | M24: =$C$7*M23/(L24+$C$7*M23) -> 5.1506249e-14 | N24: =$C$7/L24 -> 0.083333333 | O24: =IF(L24>$C$7,M24/(1-N24+N24*M24),1) -> 5.6188635e-14 | P24: =IF(L24>$C$7,1-O24*EXP(-(L24-$C$7)*$D$4/$B$4),0) -> 1 | Q24: =IF(AND(L24>$C$7,P24>=$F$4,N24<=$H$4),L24,"") -> 18
L25: 19 | M25: =$C$7*M24/(L25+$C$7*M24) -> 4.0662828e-15 | N25: =$C$7/L25 -> 0.078947368 | O25: =IF(L25>$C$7,M25/(1-N25+N25*M25),1) -> 4.4148213e-15 | P25: =IF(L25>$C$7,1-O25*EXP(-(L25-$C$7)*$D$4/$B$4),0) -> 1 | Q25: =IF(AND(L25>$C$7,P25>=$F$4,N25<=$H$4),L25,"") -> 19
L26: 20 | M26: =$C$7*M25/(L26+$C$7*M25) -> 3.0497121e-16 | N26: =$C$7/L26 -> 0.075 | O26: =IF(L26>$C$7,M26/(1-N26+N26*M26),1) -> 3.296986e-16 | P26: =IF(L26>$C$7,1-O26*EXP(-(L26-$C$7)*$D$4/$B$4),0) -> 1 | Q26: =IF(AND(L26>$C$7,P26>=$F$4,N26<=$H$4),L26,"") -> 20
L27: 21 | M27: =$C$7*M26/(L27+$C$7*M26) -> 2.1783658e-17 | N27: =$C$7/L27 -> 0.071428571 | O27: =IF(L27>$C$7,M27/(1-N27+N27*M27),1) -> 2.3459324e-17 | P27: =IF(L27>$C$7,1-O27*EXP(-(L27-$C$7)*$D$4/$B$4),0) -> 1 | Q27: =IF(AND(L27>$C$7,P27>=$F$4,N27<=$H$4),L27,"") -> 21
... L46: 40 | M46: =$C$7*M45/(L46+$C$7*M45) -> 3.0238732e-42 | N46: =$C$7/L46 -> 0.0375 | O46: =IF(L46>$C$7,M46/(1-N46+N46*M46),1) -> 3.1416864e-42 | P46: =IF(L46>$C$7,1-O46*EXP(-(L46-$C$7)*$D$4/$B$4),0) -> 1 | Q46: =IF(AND(L46>$C$7,P46>=$F$4,N46<=$H$4),L46,"") -> 40
L48: c | M48: Erlang B | N48: ρ | O48: P espera | P48: SL | Q48: c factible
L49: 1 | M49: =$C$8/(1+$C$8) -> 0.71428571 | N49: =$C$8/L49 -> 2.5 | O49: =IF(L49>$C$8,M49/(1-N49+N49*M49),1) -> 1 | P49: =IF(L49>$C$8,1-O49*EXP(-(L49-$C$8)*$D$4/$B$4),0) -> 0 | Q49: =IF(AND(L49>$C$8,P49>=$F$4,N49<=$H$4),L49,"")
L50: 2 | M50: =$C$8*M49/(L50+$C$8*M49) -> 0.47169811 | N50: =$C$8/L50 -> 1.25 | O50: =IF(L50>$C$8,M50/(1-N50+N50*M50),1) -> 1 | P50: =IF(L50>$C$8,1-O50*EXP(-(L50-$C$8)*$D$4/$B$4),0) -> 0 | Q50: =IF(AND(L50>$C$8,P50>=$F$4,N50<=$H$4),L50,"")
L51: 3 | M51: =$C$8*M50/(L51+$C$8*M50) -> 0.28216704 | N51: =$C$8/L51 -> 0.83333333 | O51: =IF(L51>$C$8,M51/(1-N51+N51*M51),1) -> 0.70224719 | P51: =IF(L51>$C$8,1-O51*EXP(-(L51-$C$8)*$D$4/$B$4),0) -> 0.7416577 | Q51: =IF(AND(L51>$C$8,P51>=$F$4,N51<=$H$4),L51,"")
L52: 4 | M52: =$C$8*M51/(L52+$C$8*M51) -> 0.14991605 | N52: =$C$8/L52 -> 0.625 | O52: =IF(L52>$C$8,M52/(1-N52+N52*M52),1) -> 0.3198567 | P52: =IF(L52>$C$8,1-O52*EXP(-(L52-$C$8)*$D$4/$B$4),0) -> 0.98407527 | Q52: =IF(AND(L52>$C$8,P52>=$F$4,N52<=$H$4),L52,"") -> 4
L53: 5 | M53: =$C$8*M52/(L53+$C$8*M52) -> 0.069731117 | N53: =$C$8/L53 -> 0.5 | O53: =IF(L53>$C$8,M53/(1-N53+N53*M53),1) -> 0.1303713 | P53: =IF(L53>$C$8,1-O53*EXP(-(L53-$C$8)*$D$4/$B$4),0) -> 0.99912157 | Q53: =IF(AND(L53>$C$8,P53>=$F$4,N53<=$H$4),L53,"") -> 5
L54: 6 | M54: =$C$8*M53/(L54+$C$8*M53) -> 0.028234295 | N54: =$C$8/L54 -> 0.41666667 | O54: =IF(L54>$C$8,M54/(1-N54+N54*M54),1) -> 0.047444812 | P54: =IF(L54>$C$8,1-O54*EXP(-(L54-$C$8)*$D$4/$B$4),0) -> 0.99995674 | Q54: =IF(AND(L54>$C$8,P54>=$F$4,N54<=$H$4),L54,"") -> 6
L55: 7 | M55: =$C$8*M54/(L55+$C$8*M54) -> 0.0099830113 | N55: =$C$8/L55 -> 0.35714286 | O55: =IF(L55>$C$8,M55/(1-N55+N55*M55),1) -> 0.015443477 | P55: =IF(L55>$C$8,1-O55*EXP(-(L55-$C$8)*$D$4/$B$4),0) -> 0.99999809 | Q55: =IF(AND(L55>$C$8,P55>=$F$4,N55<=$H$4),L55,"") -> 7
L56: 8 | M56: =$C$8*M55/(L56+$C$8*M55) -> 0.0031099888 | N56: =$C$8/L56 -> 0.3125 | O56: =IF(L56>$C$8,M56/(1-N56+N56*M56),1) -> 0.0045172344 | P56: =IF(L56>$C$8,1-O56*EXP(-(L56-$C$8)*$D$4/$B$4),0) -> 0.99999992 | Q56: =IF(AND(L56>$C$8,P56>=$F$4,N56<=$H$4),L56,"") -> 8
L57: 9 | M57: =$C$8*M56/(L57+$C$8*M56) -> 0.00086314013 | N57: =$C$8/L57 -> 0.27777778 | O57: =IF(L57>$C$8,M57/(1-N57+N57*M57),1) -> 0.0011947205 | P57: =IF(L57>$C$8,1-O57*EXP(-(L57-$C$8)*$D$4/$B$4),0) -> 1 | Q57: =IF(AND(L57>$C$8,P57>=$F$4,N57<=$H$4),L57,"") -> 9
L58: 10 | M58: =$C$8*M57/(L58+$C$8*M57) -> 0.00021573848 | N58: =$C$8/L58 -> 0.25 | O58: =IF(L58>$C$8,M58/(1-N58+N58*M58),1) -> 0.00028763062 | P58: =IF(L58>$C$8,1-O58*EXP(-(L58-$C$8)*$D$4/$B$4),0) -> 1 | Q58: =IF(AND(L58>$C$8,P58>=$F$4,N58<=$H$4),L58,"") -> 10
L59: 11 | M59: =$C$8*M58/(L59+$C$8*M58) -> 4.9029069e-05 | N59: =$C$8/L59 -> 0.22727273 | O59: =IF(L59>$C$8,M59/(1-N59+N59*M59),1) -> 6.3448468e-05 | P59: =IF(L59>$C$8,1-O59*EXP(-(L59-$C$8)*$D$4/$B$4),0) -> 1 | Q59: =IF(AND(L59>$C$8,P59>=$F$4,N59<=$H$4),L59,"") -> 11
L60: 12 | M60: =$C$8*M59/(L60+$C$8*M59) -> 1.0214285e-05 | N60: =$C$8/L60 -> 0.20833333 | O60: =IF(L60>$C$8,M60/(1-N60+N60*M60),1) -> 1.290222e-05 | P60: =IF(L60>$C$8,1-O60*EXP(-(L60-$C$8)*$D$4/$B$4),0) -> 1 | Q60: =IF(AND(L60>$C$8,P60>=$F$4,N60<=$H$4),L60,"") -> 12
L61: 13 | M61: =$C$8*M60/(L61+$C$8*M60) -> 1.9642817e-06 | N61: =$C$8/L61 -> 0.19230769 | O61: =IF(L61>$C$8,M61/(1-N61+N61*M61),1) -> 2.4319667e-06 | P61: =IF(L61>$C$8,1-O61*EXP(-(L61-$C$8)*$D$4/$B$4),0) -> 1 | Q61: =IF(AND(L61>$C$8,P61>=$F$4,N61<=$H$4),L61,"") -> 13
...
